2018-04-19 16:50:18,258 ERROR: Exception on / [GET] [in c:\program files\anaconda3\lib\site-packages\flask\app.py:1560]
Traceback (most recent call last):
  File "c:\program files\anaconda3\lib\site-packages\sqlalchemy\engine\base.py", line 1182, in _execute_context
    context)
  File "c:\program files\anaconda3\lib\site-packages\sqlalchemy\engine\default.py", line 470, in do_execute
    cursor.execute(statement, parameters)
sqlite3.OperationalError: no such table: user

The above exception was the direct cause of the following exception:

Traceback (most recent call last):
  File "c:\program files\anaconda3\lib\site-packages\flask\app.py", line 1982, in wsgi_app
    response = self.full_dispatch_request()
  File "c:\program files\anaconda3\lib\site-packages\flask\app.py", line 1614, in full_dispatch_request
    rv = self.handle_user_exception(e)
  File "c:\program files\anaconda3\lib\site-packages\flask\app.py", line 1517, in handle_user_exception
    reraise(exc_type, exc_value, tb)
  File "c:\program files\anaconda3\lib\site-packages\flask\_compat.py", line 33, in reraise
    raise value
  File "c:\program files\anaconda3\lib\site-packages\flask\app.py", line 1610, in full_dispatch_request
    rv = self.preprocess_request()
  File "c:\program files\anaconda3\lib\site-packages\flask\app.py", line 1831, in preprocess_request
    rv = func()
  File "C:\Users\arnar\Documents\GitHub\vefur_lokaverk\vsh_lokaverk\app\main\routes.py", line 16, in before_request
    if current_user.is_authenticated:
  File "c:\program files\anaconda3\lib\site-packages\werkzeug\local.py", line 343, in __getattr__
    return getattr(self._get_current_object(), name)
  File "c:\program files\anaconda3\lib\site-packages\werkzeug\local.py", line 302, in _get_current_object
    return self.__local()
  File "c:\program files\anaconda3\lib\site-packages\flask_login\utils.py", line 26, in <lambda>
    current_user = LocalProxy(lambda: _get_user())
  File "c:\program files\anaconda3\lib\site-packages\flask_login\utils.py", line 335, in _get_user
    current_app.login_manager._load_user()
  File "c:\program files\anaconda3\lib\site-packages\flask_login\login_manager.py", line 359, in _load_user
    return self.reload_user()
  File "c:\program files\anaconda3\lib\site-packages\flask_login\login_manager.py", line 321, in reload_user
    user = self.user_callback(user_id)
  File "C:\Users\arnar\Documents\GitHub\vefur_lokaverk\vsh_lokaverk\app\models.py", line 120, in load_user
    return User.query.get(int(id))
  File "c:\program files\anaconda3\lib\site-packages\sqlalchemy\orm\query.py", line 831, in get
    return self._get_impl(ident, loading.load_on_ident)
  File "c:\program files\anaconda3\lib\site-packages\sqlalchemy\orm\query.py", line 864, in _get_impl
    return fallback_fn(self, key)
  File "c:\program files\anaconda3\lib\site-packages\sqlalchemy\orm\loading.py", line 223, in load_on_ident
    return q.one()
  File "c:\program files\anaconda3\lib\site-packages\sqlalchemy\orm\query.py", line 2749, in one
    ret = self.one_or_none()
  File "c:\program files\anaconda3\lib\site-packages\sqlalchemy\orm\query.py", line 2719, in one_or_none
    ret = list(self)
  File "c:\program files\anaconda3\lib\site-packages\sqlalchemy\orm\query.py", line 2790, in __iter__
    return self._execute_and_instances(context)
  File "c:\program files\anaconda3\lib\site-packages\sqlalchemy\orm\query.py", line 2813, in _execute_and_instances
    result = conn.execute(querycontext.statement, self._params)
  File "c:\program files\anaconda3\lib\site-packages\sqlalchemy\engine\base.py", line 945, in execute
    return meth(self, multiparams, params)
  File "c:\program files\anaconda3\lib\site-packages\sqlalchemy\sql\elements.py", line 263, in _execute_on_connection
    return connection._execute_clauseelement(self, multiparams, params)
  File "c:\program files\anaconda3\lib\site-packages\sqlalchemy\engine\base.py", line 1053, in _execute_clauseelement
    compiled_sql, distilled_params
  File "c:\program files\anaconda3\lib\site-packages\sqlalchemy\engine\base.py", line 1189, in _execute_context
    context)
  File "c:\program files\anaconda3\lib\site-packages\sqlalchemy\engine\base.py", line 1393, in _handle_dbapi_exception
    exc_info
  File "c:\program files\anaconda3\lib\site-packages\sqlalchemy\util\compat.py", line 203, in raise_from_cause
    reraise(type(exception), exception, tb=exc_tb, cause=cause)
  File "c:\program files\anaconda3\lib\site-packages\sqlalchemy\util\compat.py", line 186, in reraise
    raise value.with_traceback(tb)
  File "c:\program files\anaconda3\lib\site-packages\sqlalchemy\engine\base.py", line 1182, in _execute_context
    context)
  File "c:\program files\anaconda3\lib\site-packages\sqlalchemy\engine\default.py", line 470, in do_execute
    cursor.execute(statement, parameters)
sqlalchemy.exc.OperationalError: (sqlite3.OperationalError) no such table: user [SQL: 'SELECT user.id AS user_id, user.username AS user_username, user.email AS user_email, user.password_hash AS user_password_hash, user.about_me AS user_about_me, user.last_seen AS user_last_seen \nFROM user \nWHERE user.id = ?'] [parameters: (2,)]
2018-04-19 16:52:40,498 INFO: Microblog startup [in C:\Users\arnar\Documents\GitHub\vefur_lokaverk\vsh_lokaverk\app\__init__.py:77]
